apscheduler.executors.default - run_job(line:131) - Job "training_phase (trigger: interval[0:00:01], next run at: 2024-04-03 18:59:33 UTC)" raised an exception
Traceback (most recent call last):
  File "/usr/local/lib/python3.10/site-packages/apscheduler/executors/base.py", line 125, in run_job
    retval = job.func(*job.args, **job.kwargs)
  File "/app/global_controller.py", line 1309, in training_phase
    if os.path.getsize(trainig_input_trace_file) == 0:
  File "/usr/local/lib/python3.10/genericpath.py", line 50, in getsize
    return os.stat(filename).st_size
FileNotFoundError: [Errno 2] No such file or directory: 'trace.csv'
__main__ - filter_incomplete_traces(line:1254) - !!! ERROR: len(complete_traces[us-east-1]) == 0
